Workbook

Sheet Registre Equipements
A1: REGISTRE DES EQUIPEMENTS - FABLAB UNIVERSIAPOLIS POLYTECHNIQUE
A2: Etape 2 du plan projet GMAO - Source: INVENTAIRE_PHYSIQUE_UNIVERSIAPOLIS.xlsx (Localisation: FAB LAB, Niveau: LES DOMES) - Date d'application : Juillet 2026
A4: N° | B4: Code equipement | C4: Designation | D4: Description / Caracteristiques | E4: Categorie | F4: Quantite | G4: Etat
A5: 1 | B5: FL-001 | C5: BUREAU | D5: 160*80 EN MDF | E5: Mobilier | F5: 2 | G5: BON
A6: 2 | B6: FL-002 | C6: TABLE DE REUNION | D6: 220*100 STRATY DECOR | E6: Mobilier | F6: 1 | G6: BON
A7: 3 | B7: FL-003 | C7: TABLE DE REUNION | D7: 140*140 cm EN MDF | E7: Mobilier | F7: 4 | G7: BON
A8: 4 | B8: FL-004 | C8: TABLE DE TRAVAIL | D8: 180*80 MDF ET METAL | E8: Mobilier | F8: 3 | G8: BON
A9: 5 | B9: FL-005 | C9: TIRIOIR | D9: 80*50 EN MDF 1 PORTES | E9: Mobilier - Rangement | F9: 2 | G9: BON
A10: 6 | B10: FL-006 | C10: TIRIOIR | D10: 80*50 EN MDF 1 PORTES | E10: Mobilier - Rangement | F10: 1 | G10: BON
A11: 7 | B11: FL-007 | C11: TIRIOIR | D11: 150*100 EN MDF 2 PORTES | E11: Mobilier - Rangement | F11: 2 | G11: BON
A12: 8 | B12: FL-008 | C12: POUF | D12: POUR ROND 50*50 BOIS ET SIMILI CUIR | E12: Mobilier | F12: 8 | G12: BON
A13: 9 | B13: FL-009 | C13: CLIMATISSEUR | D13: ARMAOIRE 60000BTU | E13: Equipement CVC | F13: 2 | G13: BON
A14: 10 | B14: FL-010 | C14: TELEVISION NOIRE | D14: PLASMA 43" | E14: Equipement audiovisuel | F14: 1 | G14: BON
A15: 11 | B15: FL-011 | C15: RECEPTEUR | D15: BOITIER ANDROID | E15: Equipement audiovisuel | F15: 1 | G15: BON
A16: 12 | B16: FL-012 | C16: TABLEAU D'AFFICHAGE | D16: 100*70 BLANC | E16: Mobilier | F16: 1 | G16: BON
... A20: 16 | B20: FL-016 | C20: IMPRESSION 3D | D20: SCHENZHEN CREALITY 3D TECHNOLOGY | E20: Machine Fablab - Impression 3D | F20: 2 | G20: BON
A21: 17 | B21: FL-017 | C21: IMPRESSION 3D | E21: Machine Fablab - Impression 3D | F21: 1 | G21: BON
A22: 18 | B22: FL-018 | C22: DECOUPE LASER | D22: PIPROD.COM | E22: Machine Fablab - Decoupe laser | F22: 1 | G22: BON
A23: 19 | B23: FL-019 | C23: DECOUPE CNC | D23: PIPROD.COM | E23: Machine Fablab - Decoupe/Usinage CNC | F23: 1 | G23: BON
A24: 20 | B24: FL-020 | C24: DECOUPE CNC | D24: TECHNO DRILL 3 | E24: Machine Fablab - Decoupe/Usinage CNC | F24: 1 | G24: BON
A25: 21 | B25: FL-021 | C25: COMPRESSEUR | D25: DE 8 BAR | E25: Equipement atelier | F25: 1 | G25: BON
A26: 22 | B26: FL-022 | C26: ASPIRATEUR | D26: DE POUSSIERE | E26: Equipement atelier | F26: 1 | G26: BON
A27: 23 | B27: FL-023 | C27: PILVERISATEUR | D27: ELECTIQUE | E27: Equipement atelier | F27: 1 | G27: BON
A28: 24 | B28: FL-024 | C28: MACHINE WC 3000 | D28: AVEC DECOUPE LASER | E28: Machine Fablab - Decoupe laser | F28: 1 | G28: BON
A29: 25 | B29: FL-025 | C29: PERSEUSE | E29: Outillage atelier | F29: 1 | G29: BON
A30: 26 | B30: FL-026 | C30: PLIEUSE | D30: DE PERSEGLACE | E30: Machine Fablab - Faconnage | F30: 1 | G30: BON
A31: 27 | B31: FL-027 | C31: SCOPE | D31: NUMERIQUE | E31: Instrument de mesure | F31: 1 | G31: BON
A32: 28 | B32: FL-028 | C32: SCOPE | D32: ANALOGIQUE | E32: Instrument de mesure | F32: 2 | G32: BON
A33: 29 | B33: FL-029 | C33: SCOPE | D33: ANALOGIQUE | E33: Instrument de mesure | F33: 1 | G33: BON
A34: 30 | B34: FL-030 | C34: BALANCE | D34: AVEC AFFICHAGE | E34: Instrument de mesure | F34: 1 | G34: BON
A35: 31 | B35: FL-031 | C35: BALANCE | E35: Instrument de mesure | F35: 1 | G35: BON
A36: 32 | B36: FL-032 | C36: ADJUSTABLE DC | D36: POWER SUPPLY | E36: Instrument electronique | F36: 1 | G36: BON
A37: 33 | B37: FL-033 | C37: RECHEAU | D37: REWORK SOLDERING | E37: Equipement electronique | F37: 1 | G37: BON
A38: 34 | B38: FL-034 | C38: POMLE A EAU | D38: KNF | E38: Equipement atelier | F38: 1 | G38: BON
A39: 35 | B39: FL-035 | C39: PHOTOCENTRIC 3D | D39: EN 3D | E39: Machine Fablab - Impression 3D | F39: 1 | G39: BON
A40: 36 | B40: FL-036 | C40: APPAREIL PHOTO 3D | D40: EN SCAN | E40: Equipement scan 3D | F40: 1 | G40: BON
A41: 37 | B41: FL-037 | C41: INTERTEK | E41: A identifier | F41: 1 | G41: BON
A42: 38 | B42: FL-038 | C42: IMPRESSION 3D | E42: Machine Fablab - Impression 3D | F42: 2 | G42: BON
A43: 39 | B43: FL-039 | C43: MACHINE AIR CHAUD | E43: Equipement atelier | F43: 1 | G43: BON
A44: 40 | B44: FL-040 | C44: DISTRIBUTEUR MANUEL | D44: DE GEL DESINFECTANT | E44: Hygiene / Consommable | F44: 1 | G44: BON
...

Sheet Synthese par categorie
A1: SYNTHESE DES EQUIPEMENTS FABLAB PAR CATEGORIE
A3: Categorie | B3: Nombre de lignes d'inventaire | C3: Quantite totale
A4: Mobilier | B4: =COUNTIF('Registre Equipements'!E5:E44,A4) -> 8 | C4: =SUMIF('Registre Equipements'!E5:E44,A4,'Registre Equipements'!F5:F44) -> 40
A5: Mobilier - Rangement | B5: =COUNTIF('Registre Equipements'!E5:E44,A5) -> 3 | C5: =SUMIF('Registre Equipements'!E5:E44,A5,'Registre Equipements'!F5:F44) -> 5
A6: Equipement CVC | B6: =COUNTIF('Registre Equipements'!E5:E44,A6) -> 1 | C6: =SUMIF('Registre Equipements'!E5:E44,A6,'Registre Equipements'!F5:F44) -> 2
A7: Equipement audiovisuel | B7: =COUNTIF('Registre Equipements'!E5:E44,A7) -> 2 | C7: =SUMIF('Registre Equipements'!E5:E44,A7,'Registre Equipements'!F5:F44) -> 2
A8: Equipement electrique | B8: =COUNTIF('Registre Equipements'!E5:E44,A8) -> 1 | C8: =SUMIF('Registre Equipements'!E5:E44,A8,'Registre Equipements'!F5:F44) -> 1
A9: Machine Fablab - Impression 3D | B9: =COUNTIF('Registre Equipements'!E5:E44,A9) -> 4 | C9: =SUMIF('Registre Equipements'!E5:E44,A9,'Registre Equipements'!F5:F44) -> 6
A10: Machine Fablab - Decoupe laser | B10: =COUNTIF('Registre Equipements'!E5:E44,A10) -> 2 | C10: =SUMIF('Registre Equipements'!E5:E44,A10,'Registre Equipements'!F5:F44) -> 2
A11: Machine Fablab - Decoupe/Usinage CNC | B11: =COUNTIF('Registre Equipements'!E5:E44,A11) -> 2 | C11: =SUMIF('Registre Equipements'!E5:E44,A11,'Registre Equipements'!F5:F44) -> 2
A12: Equipement atelier | B12: =COUNTIF('Registre Equipements'!E5:E44,A12) -> 5 | C12: =SUMIF('Registre Equipements'!E5:E44,A12,'Registre Equipements'!F5:F44) -> 5
A13: Outillage atelier | B13: =COUNTIF('Registre Equipements'!E5:E44,A13) -> 1 | C13: =SUMIF('Registre Equipements'!E5:E44,A13,'Registre Equipements'!F5:F44) -> 1
A14: Machine Fablab - Faconnage | B14: =COUNTIF('Registre Equipements'!E5:E44,A14) -> 1 | C14: =SUMIF('Registre Equipements'!E5:E44,A14,'Registre Equipements'!F5:F44) -> 1
A15: Instrument de mesure | B15: =COUNTIF('Registre Equipements'!E5:E44,A15) -> 5 | C15: =SUMIF('Registre Equipements'!E5:E44,A15,'Registre Equipements'!F5:F44) -> 6
A16: Instrument electronique | B16: =COUNTIF('Registre Equipements'!E5:E44,A16) -> 1 | C16: =SUMIF('Registre Equipements'!E5:E44,A16,'Registre Equipements'!F5:F44) -> 1
A17: Equipement electronique | B17: =COUNTIF('Registre Equipements'!E5:E44,A17) -> 1 | C17: =SUMIF('Registre Equipements'!E5:E44,A17,'Registre Equipements'!F5:F44) -> 1
A18: Equipement scan 3D | B18: =COUNTIF('Registre Equipements'!E5:E44,A18) -> 1 | C18: =SUMIF('Registre Equipements'!E5:E44,A18,'Registre Equipements'!F5:F44) -> 1
A19: A identifier | B19: =COUNTIF('Registre Equipements'!E5:E44,A19) -> 1 | C19: =SUMIF('Registre Equipements'!E5:E44,A19,'Registre Equipements'!F5:F44) -> 1
A20: Hygiene / Consommable | B20: =COUNTIF('Registre Equipements'!E5:E44,A20) -> 1 | C20: =SUMIF('Registre Equipements'!E5:E44,A20,'Registre Equipements'!F5:F44) -> 1
A21: TOTAL | B21: =SUM(B4:B20) -> 40 | C21: =SUM(C4:C20) -> 78
